Workbook

Sheet Leia-me
A1: QIMO · Estudo de viabilidade — navio boutique próprio × charter
A3: Objetivo: comparar COMPRAR USADO × CONSTRUIR NOVO × CONTINUAR FRETANDO para operar grupos privados QIMO na Grécia/Mediterrâneo.
A4: Data-base: outubro/2026. Moeda: € (USD convertido a 1,15; BRL a 5,85).
A6: COMO USAR
A7: 1) Edite somente as células em AZUL (inputs). Amarelo = premissas-chave (semanas, semanas QIMO, tarifa, preço do navio, combustível, alíquota, hurdle).
A8: 2) Preto = fórmula. Verde = link de outra aba. Não sobrescreva fórmulas.
A9: 3) Tudo recalcula: Projecao (18 blocos = 6 opções × 3 cenários), Sensib_Semanas, Buy_Build_Charter, Financiamento e Painel.
A11: ABAS
A12: Painel — resultados-chave (TIR, VPL, payback, break-even, semanas p/ possuir = fretar, alavancagem).
A13: Premissas — gerais, cenários e as 6 opções de navio (A/B/C × novo/usado), com tipo e fonte de cada número.
A14: Tripulacao — quadro de tripulação por configuração, salários e custo anual.
A15: CAPEX_Construcao — breakdown de construção nova em 3 padrões (Premium funcional / Luxury boutique / Ultra-luxury) e custo por região.
... A31: • A margem da QIMO na venda da viagem ao cliente final existe nos dois modelos e não entra na comparação.

Sheet Painel
A1: QIMO · Navio Boutique — Painel executivo (atualiza com as Premissas)
A2: Devemos investir em um navio próprio? Leia as linhas de TIR, VPL e semanas para possuir = fretar.
A4: 1. Resultados por opção e cenário
A5: Opção / cenário | B5: CAPEX | C5: Receita a3 | D5: EBITDA a3 | E5: Margem a3 | F5: TIR 10a | G5: VPL @hurdle | H5: Payback | I5: Break-even (sem.) | J5: ROIC médio
A6: C · 36 cab/72 pax · NOVO · Conservador | B6: =Projecao!$C$41 -> 47709000 | C6: =Projecao!$C$37 -> 5039636.3 | D6: =Projecao!$C$36 -> -414300.38 | E6: =Projecao!$C$38 -> -0.082208388 | F6: =Projecao!$C$31 -> -0.11933694 | G6: =Projecao!$C$32 -> -50614480 | H6: =Projecao!$C$33 -> > 10 | I6: =Projecao!$C$40 -> 22.336282 | J6: =Projecao!$C$35 -> -0.044653027
A7: C · 36 cab/72 pax · NOVO · Base | B7: =Projecao!$C$82 -> 47709000 | C7: =Projecao!$C$78 -> 7463640 | D7: =Projecao!$C$77 -> 2338197.2 | E7: =Projecao!$C$79 -> 0.3132784 | F7: =Projecao!$C$72 -> -0.017419323 | G7: =Projecao!$C$73 -> -31517619 | H7: =Projecao!$C$74 -> > 10 | I7: =Projecao!$C$81 -> 15.763871 | J7: =Projecao!$C$76 -> 0.0026538678
A8: C · 36 cab/72 pax · NOVO · Otimista | B8: =Projecao!$C$123 -> 47709000 | C8: =Projecao!$C$119 -> 9746923.8 | D8: =Projecao!$C$118 -> 4819256.2 | E8: =Projecao!$C$120 -> 0.49443869 | F8: =Projecao!$C$113 -> 0.032259973 | G8: =Projecao!$C$114 -> -19656752 | H8: =Projecao!$C$115 -> > 10 | I8: =Projecao!$C$122 -> 12.454355 | J8: =Projecao!$C$117 -> 0.046518913
A9: C · 36 cab/72 pax · USADO · Conservador | B9: =Projecao!$C$164 -> 21400000 | C9: =Projecao!$C$160 -> 4553087.7 | D9: =Projecao!$C$159 -> -970317.6 | E9: =Projecao!$C$161 -> -0.21311199 | F9: =Projecao!$C$154 -> negativa | G9: =Projecao!$C$155 -> -29267829 | H9: =Projecao!$C$156 -> > 10 | I9: =Projecao!$C$163 -> 26.341705 | J9: =Projecao!$C$158 -> -0.0761848
A10: C · 36 cab/72 pax · USADO · Base | B10: =Projecao!$C$205 -> 21400000 | C10: =Projecao!$C$201 -> 6739969.5 | D10: =Projecao!$C$200 -> 1551373.5 | E10: =Projecao!$C$202 -> 0.23017515 | F10: =Projecao!$C$195 -> -0.026968782 | G10: =Projecao!$C$196 -> -13109788 | H10: =Projecao!$C$197 -> > 10 | I10: =Projecao!$C$204 -> 18.266043 | J10: =Projecao!$C$199 -> 0.013531768
A11: C · 36 cab/72 pax · USADO · Otimista | B11: =Projecao!$C$246 -> 21400000 | C11: =Projecao!$C$242 -> 8798058.1 | D11: =Projecao!$C$241 -> 3810395 | E11: =Projecao!$C$243 -> 0.433095 | F11: =Projecao!$C$236 -> 0.075121747 | G11: =Projecao!$C$237 -> -2822134.2 | H11: =Projecao!$C$238 -> 9.6168718 | I11: =Projecao!$C$245 -> 14.321994 | J11: =Projecao!$C$240 -> 0.095732345
A12: B · 24 cab/48 pax · NOVO · Conservador | B12: =Projecao!$C$287 -> 31940000 | C12: =Projecao!$C$283 -> 2918346.3 | D12: =Projecao!$C$282 -> -1073654.5 | E12: =Projecao!$C$284 -> -0.36789824 | F12: =Projecao!$C$277 -> negativa | G12: =Projecao!$C$278 -> -38999309 | H12: =Projecao!$C$279 -> > 10 | I12: =Projecao!$C$286 -> 31.43617 | J12: =Projecao!$C$281 -> -0.062035231
A13: B · 24 cab/48 pax · NOVO · Base | B13: =Projecao!$C$328 -> 31940000 | C13: =Projecao!$C$324 -> 4309957.9 | D13: =Projecao!$C$323 -> 569735.33 | E13: =Projecao!$C$325 -> 0.13219046 | F13: =Projecao!$C$318 -> -0.057523175 | G13: =Projecao!$C$319 -> -27191281 | H13: =Projecao!$C$320 -> > 10 | I13: =Projecao!$C$327 -> 21.445952 | J13: =Projecao!$C$322 -> -0.019153332
A14: B · 24 cab/48 pax · NOVO · Otimista | B14: =Projecao!$C$369 -> 31940000 | C14: =Projecao!$C$365 -> 5621226.2 | D14: =Projecao!$C$364 -> 2031811.2 | E14: =Projecao!$C$366 -> 0.36145337 | F14: =Projecao!$C$359 -> 0.0032103243 | G14: =Projecao!$C$360 -> -18303452 | H14: =Projecao!$C$361 -> > 10 | I14: =Projecao!$C$368 -> 16.693118 | J14: =Projecao!$C$363 -> 0.02020407
A15: B · 24 cab/48 pax · USADO · Conservador | B15: =Projecao!$C$410 -> 10600000 | C15: =Projecao!$C$406 -> 2593980.5 | D15: =Projecao!$C$405 -> -1368005.2 | E15: =Projecao!$C$407 -> -0.52737683 | F15: =Projecao!$C$400 -> negativa | G15: =Projecao!$C$401 -> -20795451 | H15: =Projecao!$C$402 -> > 10 | I15: =Projecao!$C$409 -> 37.614393 | J15: =Projecao!$C$404 -> -0.13618629
A16: B · 24 cab/48 pax · USADO · Base | B16: =Projecao!$C$451 -> 10600000 | C16: =Projecao!$C$447 -> 3827510.9 | D16: =Projecao!$C$446 -> 114574.67 | E16: =Projecao!$C$448 -> 0.029934512 | F16: =Projecao!$C$441 -> -0.13555315 | G16: =Projecao!$C$442 -> -10853228 | H16: =Projecao!$C$443 -> > 10 | I16: =Projecao!$C$450 -> 24.924682 | J16: =Projecao!$C$445 -> -0.031004396
A17: B · 24 cab/48 pax · USADO · Otimista | B17: =Projecao!$C$492 -> 10600000 | C17: =Projecao!$C$488 -> 4988649.1 | D17: =Projecao!$C$487 -> 1425156.1 | E17: =Projecao!$C$489 -> 0.28567976 | F17: =Projecao!$C$482 -> 0.026922799 | G17: =Projecao!$C$483 -> -3929847.9 | H17: =Projecao!$C$484 -> > 10 | I17: =Projecao!$C$491 -> 19.17078 | J17: =Projecao!$C$486 -> 0.06400252
A18: A · 20 cab/40 pax · NOVO · Conservador | B18: =Projecao!$C$533 -> 27370000 | C18: =Projecao!$C$529 -> 2109814.7 | D18: =Projecao!$C$528 -> -1343996.3 | E18: =Projecao!$C$530 -> -0.63702103 | F18: =Projecao!$C$523 -> negativa | G18: =Projecao!$C$524 -> -36046078 | H18: =Projecao!$C$525 -> > 10 | I18: =Projecao!$C$532 -> 42.151773 | J18: =Projecao!$C$527 -> -0.072707038
A19: A · 20 cab/40 pax · NOVO · Base | B19: =Projecao!$C$574 -> 27370000 | C19: =Projecao!$C$570 -> 3106488 | D19: =Projecao!$C$569 -> -124297.43 | E19: =Projecao!$C$571 -> -0.040012204 | F19: =Projecao!$C$564 -> -0.089715565 | G19: =Projecao!$C$565 -> -27152100 | H19: =Projecao!$C$566 -> > 10 | I19: =Projecao!$C$573 -> 27.468537 | J19: =Projecao!$C$568 -> -0.034705738
A20: A · 20 cab/40 pax · NOVO · Otimista | B20: =Projecao!$C$615 -> 27370000 | C20: =Projecao!$C$611 -> 4045822.4 | D20: =Projecao!$C$610 -> 949351.71 | E20: =Projecao!$C$612 -> 0.23464987 | F20: =Projecao!$C$605 -> -0.020016109 | G20: =Projecao!$C$606 -> -19069890 | H20: =Projecao!$C$607 -> > 10 | I20: =Projecao!$C$614 -> 20.981602 | J20: =Projecao!$C$609 -> -7.506941e-05
A21: A · 18 cab/36 pax · USADO · Conservador | B21: =Projecao!$C$656 -> 10000000 | C21: =Projecao!$C$652 -> 1812563.9 | D21: =Projecao!$C$651 -> -1451158.7 | E21: =Projecao!$C$653 -> -0.80061105 | F21: =Projecao!$C$646 -> negativa | G21: =Projecao!$C$647 -> -20202033 | H21: =Projecao!$C$648 -> > 10 | I21: =Projecao!$C$655 -> 49.466319 | J21: =Projecao!$C$650 -> -0.14632006
A22: A · 18 cab/36 pax · USADO · Base | B22: =Projecao!$C$697 -> 10000000 | C22: =Projecao!$C$693 -> 2675248.5 | D22: =Projecao!$C$692 -> -373568.54 | E22: =Projecao!$C$694 -> -0.13963882 | F22: =Projecao!$C$687 -> negativa | G22: =Projecao!$C$688 -> -12893628 | H22: =Projecao!$C$689 -> > 10 | I22: =Projecao!$C$696 -> 31.275573 | J22: =Projecao!$C$691 -> -0.06379819
A23: A · 18 cab/36 pax · USADO · Otimista | B23: =Projecao!$C$738 -> 10000000 | C23: =Projecao!$C$734 -> 3486234.7 | D23: =Projecao!$C$733 -> 566536.98 | E23: =Projecao!$C$735 -> 0.16250684 | F23: =Projecao!$C$728 -> -0.034384191 | G23: =Projecao!$C$729 -> -6642691 | H23: =Projecao!$C$730 -> > 10 | I23: =Projecao!$C$737 -> 23.635509 | J23: =Projecao!$C$732 -> 0.0099647583
A25: 2. Possuir × fretar (cenário Base)
B26: C · 36 cab/72 pax · NOVO | C26: C · 36 cab/72 pax · USADO | D26: B · 24 cab/48 pax · NOVO | E26: B · 24 cab/48 pax · USADO | F26: A · 20 cab/40 pax · NOVO | G26: A · 18 cab/36 pax · USADO
A27: Semanas p/ possuir = fretar | B27: =Buy_Build_Charter!B14 -> 41.664627 | C27: =Buy_Build_Charter!C14 -> 31.992325 | D27: =Buy_Build_Charter!D14 -> 53.901322 | E27: =Buy_Build_Charter!E14 -> 38.319572 | F27: =Buy_Build_Charter!F14 -> 70.039246 | G27: =Buy_Build_Charter!G14 -> 49.643183
A28: Custo próprio vs tarifa @26 sem. | B28: =Buy_Build_Charter!B17 -> 0.49148544 | C28: =Buy_Build_Charter!C17 -> 0.18329418 | D28: =Buy_Build_Charter!D17 -> 0.83118056 | E28: =Buy_Build_Charter!E17 -> 0.35275618 | F28: =Buy_Build_Charter!F17 -> 1.2302753 | G28: =Buy_Build_Charter!G17 -> 0.64744667
A29: Custo próprio vs tarifa @30 sem. | B29: =Buy_Build_Charter!B19 -> 0.31718566 | C29: =Buy_Build_Charter!C19 -> 0.052816005 | D29: =Buy_Build_Charter!D19 -> 0.61708447 | E29: =Buy_Build_Charter!E19 -> 0.20645818 | F29: =Buy_Build_Charter!F19 -> 0.96939416 | G29: =Buy_Build_Charter!G19 -> 0.46618899
A30: CAPEX máx. justificável @26 sem. | B30: =Buy_Build_Charter!B21 -> 12419489 | C30: =Buy_Build_Charter!C21 -> 7568858.7 | D30: =Buy_Build_Charter!D21 -> 2953740 | E30: =Buy_Build_Charter!E21 -> 200401.97 | F30: =Buy_Build_Charter!F21 -> 0 | G30: =Buy_Build_Charter!G21 -> 0
A31: CAPEX máx. justificável @30 sem. | B31: =Buy_Build_Charter!B22 -> 17127342 | C31: =Buy_Build_Charter!C22 -> 11468382 | D31: =Buy_Build_Charter!D22 -> 5486712.9 | E31: =Buy_Build_Charter!E22 -> 2228386.8 | F31: =Buy_Build_Charter!F22 -> 891808.34 | G31: =Buy_Build_Charter!G22 -> 0
A32: CAPEX do caso | B32: =Buy_Build_Charter!B6 -> 47709000 | C32: =Buy_Build_Charter!C6 -> 21400000 | D32: =Buy_Build_Charter!D6 -> 31940000 | E32: =Buy_Build_Charter!E6 -> 10600000 | F32: =Buy_Build_Charter!F6 -> 27370000 | G32: =Buy_Build_Charter!G6 -> 10000000
A34: 3. Charter — custo efetivo para a QIMO (Base)
A35: Navio | B35: Tarifa/sem. | C35: Navio (tarifa+APA+IVA) | D35: Total semana | E35: Por passageiro
A36: 72 pax (Voyager) | B36: =Charter!C7 -> 280000 | C36: =Charter!C13 -> 403200 | D36: =Charter!C14 -> 463600 | E36: =Charter!C16 -> 6438.8889
A37: 48–49 pax | B37: =Charter!C21 -> 135000 | C37: =Charter!C27 -> 194400 | D37: =Charter!C28 -> 229950 | E37: =Charter!C30 -> 4692.8571
A38: 36–40 pax | B38: =Charter!C35 -> 95000 | C38: =Charter!C41 -> 136800 | D38: =Charter!C42 -> 162500 | E38: =Charter!C44 -> 4513.8889
A40: 4. Alavancagem — TIR do acionista (cenário Base)
A41: Opção | B41: 100% equity | C41: 50/50 | D41: 30/70 | E41: Equity 30/70 | F41: DSCR mín 50/50 | G41: DSCR mín 30/70 | H41: Serv. dívida 30/70
A42: C · 36 cab/72 pax · USADO | B42: =Financiamento!$C$16 -> -0.026968782 | C42: =Financiamento!$C$34 -> negativa | D42: =Financiamento!$C$52 -> negativa | E42: =Financiamento!$C$51 -> 6420000 | F42: =Financiamento!$C$35 -> 0.58019412 | G42: =Financiamento!$C$53 -> 0.41442437 | H42: =Financiamento!$C$54 -> 2010316
A43: C · 36 cab/72 pax · NOVO | B43: =Financiamento!$C$70 -> -0.017419323 | C43: =Financiamento!$C$88 -> negativa | D43: =Financiamento!$C$106 -> negativa | E43: =Financiamento!$C$105 -> 14312700 | F43: =Financiamento!$C$89 -> 0.46948988 | G43: =Financiamento!$C$107 -> 0.33534991 | H43: =Financiamento!$C$108 -> 4481783.5
A44: B · 24 cab/48 pax · USADO | B44: =Financiamento!$C$124 -> -0.13555315 | C44: =Financiamento!$C$142 -> negativa | D44: =Financiamento!$C$160 -> negativa | E44: =Financiamento!$C$159 -> 3180000 | F44: =Financiamento!$C$143 -> -0.33346973 | G44: =Financiamento!$C$161 -> -0.23819266 | H44: =Financiamento!$C$162 -> 995764

Sheet Premissas
A1: QIMO · Navio Boutique — Premissas (editáveis)
A2: Azul = input editável · Preto = fórmula · Verde = link de outra aba · Amarelo = premissa-chave. Tipo: CONFIRMADO / ESTIMATIVA / PREMISSA. Valores em € (2026) salvo indicação.
A4: A. PREMISSAS GERAIS
A5: Parâmetro | B5: Valor | C5: Unidade | D5: Tipo | J5: Fonte / racional
A6: Câmbio EUR/USD | B6: 1.15 | C6: USD por € | D6: CONFIRMADO | J6: 1,1469 em 16/09/2026 (poundsterlinglive.com/history/EUR-USD-2026); arredondado para 1,15
A7: Câmbio EUR/BRL | B7: 5.85 | C7: BRL por € | D7: CONFIRMADO | J7: ≈5,84 no início de out/2026 (longforecast.com/eur-to-brl)
A8: Inflação de tarifas (a.a.) | B8: 0.025 | C8: % | D8: PREMISSA | J8: Reajuste anual de tarifas de charter/cabine
A9: Inflação de custos (a.a.) | B9: 0.03 | C9: % | D9: PREMISSA | J9: Acordos salariais gregos +5% (2025) e +2% (2026); IBF +3,5% (2026)
A10: Taxa de desconto / hurdle (€, desalavancada) | B10: 0.1 | C10: % | D10: PREMISSA | J10: Ativo de nicho, 1º navio, operador novo: EURIBOR ~2,4% + prêmio de risco de ativo/operador
A11: Alíquota efetiva de IR sobre lucro (CFC Brasil) | B11: 0.34 | C11: % | D11: PREMISSA | J11: Lei 12.973/2014: lucro da controlada no exterior tributado anualmente no Brasil (IRPJ+CSLL 34%), com crédito do imposto pago lá fora. A tonnage tax local NÃO reduz a carga final. Validar com tributarista
A12: Comissão de broker/agência (charter e cabines de terceiros) | B12: 0.15 | C12: % | D12: ESTIMATIVA | J12: Prática de mercado: 10–20%; 15% central
A13: Receita líquida a bordo (margem bebidas premium/spa/extras) | B13: 150 | C13: €/pax-semana | D13: PREMISSA | J13: Margem sobre APA/consumo extra; conservador
A14: Ocupação média de leitos (alimentação/consumo) | B14: 0.9 | C14: % | D14: PREMISSA | J14: Grupos privados raramente lotam 100% dos leitos
A15: Alimentação de hóspedes (full board de luxo) | B15: 55 | C15: €/pax-dia | D15: ESTIMATIVA | J15: Benchmark de €45–65/pax-dia para small ship de luxo no Med (pesquisa OPEX)
A16: Lavanderia, amenities, consumíveis | B16: 10 | C16: €/pax-dia | D16: ESTIMATIVA | J16: €8–12/pax-dia
A17: Alimentação da tripulação | B17: 13 | C17: €/tripulante-dia | D17: ESTIMATIVA | J17: €12–15/tripulante-dia
... A25: Balloon no vencimento | B25: 0.3 | C25: % da dívida | D25: ESTIMATIVA | J25: Estrutura usual com balão
A27: B. CENÁRIOS (Conservador / Base / Otimista)
A28: Parâmetro | B28: Conservador | C28: Base | D28: Otimista | E28: Unidade | F28: Tipo | J28: Fonte / racional
A29: Semanas operadas por ano (regime) | B29: 20 | C29: 26 | D29: 30 | E29: semanas | F29: PREMISSA | J29: Temporada Med = ~28–30 semanas (abr–out). Variety opera Grécia sex a sex, abr–out
A30: …das quais: semanas QIMO (uso próprio) | B30: 6 | C30: 8 | D30: 12 | E30: semanas | F30: PREMISSA | J30: Volume QIMO a validar internamente — principal driver estratégico
A31: …das quais: semanas de venda de cabines | B31: 4 | C31: 4 | D31: 4 | E31: semanas | F31: PREMISSA | J31: Semanas de ombro vendidas por cabine
A32: Multiplicador de tarifa (vs. base de mercado) | B32: 0.9 | C32: 1 | D32: 1.1 | E32: x | F32: PREMISSA | J32: Captura a faixa baixa/alta das tarifas confirmadas
A33: Multiplicador de OPEX | B33: 1.1 | C33: 1 | D33: 0.95 | E33: x | F33: PREMISSA | J33: Faixa de OPEX da pesquisa: €5,2–6,8M p/ 72 pax
A34: Preço do MGO | B34: 1400 | C34: 1000 | D34: 750 | E34: US$/t | F34: CONFIRMADO (faixa) | J34: Pireu MGO: US$683–690/t (abr/26) → US$1.657/t (18/09/26, choque no Oriente Médio) (shipandbunker.com)
A35: Valor residual ano 10 — navio NOVO (% do CAPEX) | B35: 0.45 | C35: 0.55 | D35: 0.65 | E35: % | F35: ESTIMATIVA | J35: 45–65% em mercado normal; 25–40% em mercado estressado (pesquisa de estaleiros, §5)
A36: Valor residual ano 10 — navio USADO (% do CAPEX) | B36: 0.4 | C36: 0.5 | D36: 0.6 | E36: % | F36: ESTIMATIVA | J36: Navios pequenos antigos mantêm valor nominal (ex.: Galileo, 1992, ainda vale ~€7M)
A37: Ramp-up do ano 1 (% das semanas) | B37: 0.75 | C37: 0.85 | D37: 0.95 | E37: % | F37: PREMISSA | J37: Primeiro ano de operador novo
A38: Ocupação das semanas de venda por cabine | B38: 0.65 | C38: 0.75 | D38: 0.85 | E38: % | F38: PREMISSA
A40: C. OPÇÕES DE EMBARCAÇÃO (tamanho × modelo)
A41: Parâmetro | B41: C · 36 cab/72 pax · NOVO | C41: C · 36 cab/72 pax · USADO | D41: B · 24 cab/48 pax · NOVO | E41: B · 24 cab/48 pax · USADO | F41: A · 20 cab/40 pax · NOVO | G41: A · 18 cab/36 pax · USADO | H41: Unidade | I41: Tipo | J41: Fonte / racional
A42: Características
A43: Cabines | B43: 36 | C43: 36 | D43: 24 | E43: 24 | F43: 20 | G43: 18 | H43: un | I43: PREMISSA | J43: A/B/C do briefing. B = 24 cab/48 pax (≤49 pax: regime grego de iate profissional, Lei 4926/2022)
A44: Passageiros (leitos) | B44: 72 | C44: 72 | D44: 48 | E44: 48 | F44: 40 | G44: 36 | H44: pax | I44: PREMISSA
A45: Tripulação | B45: 28 | C45: 28 | D45: 20 | E45: 20 | F45: 17 | G45: 16 | H45: pessoas | I45: ESTIMATIVA | J45: Variety Voyager: 29–32 trip. p/ 72 pax; Galileo/Harmony V: 16–18 p/ 49 pax (CONFIRMADO)
A46: Comprimento (LOA) | B46: 62 | C46: 64 | D46: 50 | E46: 47 | F46: 45 | G46: 63 | H46: m | I46: ESTIMATIVA | J46: Usados: B = anúncio #1048634 (47 m); A = anúncio #1091239 (63 m, veleiro); C = estimativa (sem anúncio de 72 pax)
A47: CAPEX
A48: Preço de compra / contrato de construção | B48: =CAPEX_Construcao!$C$9 -> 41850000 | C48: 17000000 | D48: 28000000 | E48: 7000000 | F48: 24000000 | G48: 8300000 | H48: € | I48: ver fonte | J48: C_NOVO: luxury boutique, Turquia €34–46M (ESTIMATIVA; Voyager €29M em 2012 ≈ €38–42M hoje). C_USADO: ESTIMATIVA €12–25M (nenhum anúncio de 72 pax encontrado). B_USADO: CONFIRMADO anúncio #1048634 (€7,0M, 49 pax, bandeira grega). A_USADO: CONFIRMADO anúncio #1091239 (€8,3M, 36 pax, Brodosplit 2019). B/A_NOVO: ESTIMATIVA ~€580–600k/leito (navio menor = custo/leito maior)
A49: Retrofit / upgrade para padrão QIMO | B49: 0 | C49: 3000000 | D49: 0 | E49: 2500000 | F49: 0 | G49: 1000000 | H49: € | I49: ESTIMATIVA | J49: Cabines + áreas sociais + marina + docagem de entrada; ~€60–80k por cabine + sistemas
A50: Contingência (% de construção ou retrofit) | B50: =CAPEX_Construcao!$G$27 -> 0.08 | C50: 0.2 | D50: 0.08 | E50: 0.2 | F50: 0.08 | G50: 0.2 | H50: % | I50: ESTIMATIVA | J50: Construção: 7–10%; retrofit de navio usado: 15–25%
...

Sheet Tripulacao
A1: Tripulação — quadro, salários e custo anual
A2: Salários brutos mensais (€). Postos-chave pagos 12 meses × fator de rodízio; sazonais pagos por 'meses sazonais'. Fonte: UKSA Superyacht Salary Guide 2025, Quay Crew, escalas de cruzeiro (Celestyal) — ver Fontes.
A4: Configuração C — 36 cabines / 72 pax
A5: Função | B5: Qtd | C5: €/mês | D5: Posto-chave (1=sim) | E5: Meses pagos | F5: Custo anual (€)
A6: Comandante (Master) | B6: 1 | C6: 12000 | D6: 1 | E6: =IF(D6=1,12*Premissas!$B$21,Premissas!$B$22) -> 15.6 | F6: =B6*C6*E6 -> 187200
A7: Imediato (Chief Officer) | B7: 1 | C7: 7000 | D7: 1 | E7: =IF(D7=1,12*Premissas!$B$21,Premissas!$B$22) -> 15.6 | F7: =B7*C7*E7 -> 109200
A8: 2º Oficial / Navegação | B8: 1 | C8: 4500 | D8: 0 | E8: =IF(D8=1,12*Premissas!$B$21,Premissas!$B$22) -> 8 | F8: =B8*C8*E8 -> 36000
A9: Contramestre (Bosun) | B9: 1 | C9: 3500 | D9: 0 | E9: =IF(D9=1,12*Premissas!$B$21,Premissas!$B$22) -> 8 | F9: =B9*C9*E9 -> 28000
A10: Marinheiros / tender drivers | B10: 2 | C10: 2800 | D10: 0 | E10: =IF(D10=1,12*Premissas!$B$21,Premissas!$B$22) -> 8 | F10: =B10*C10*E10 -> 44800
A11: Chefe de Máquinas | B11: 1 | C11: 9000 | D11: 1 | E11: =IF(D11=1,12*Premissas!$B$21,Premissas!$B$22) -> 15.6 | F11: =B11*C11*E11 -> 140400
A12: 2º Maquinista | B12: 1 | C12: 5500 | D12: 1 | E12: =IF(D12=1,12*Premissas!$B$21,Premissas!$B$22) -> 15.6 | F12: =B12*C12*E12 -> 85800
A13: 3º Maquinista / ETO | B13: 1 | C13: 4500 | D13: 0 | E13: =IF(D13=1,12*Premissas!$B$21,Premissas!$B$22) -> 8 | F13: =B13*C13*E13 -> 36000
A14: Hotel Manager | B14: 1 | C14: 6500 | D14: 1 | E14: =IF(D14=1,12*Premissas!$B$21,Premissas!$B$22) -> 15.6 | F14: =B14*C14*E14 -> 101400
A15: Recepção / Purser | B15: 1 | C15: 3000 | D15: 0 | E15: =IF(D15=1,12*Premissas!$B$21,Premissas!$B$22) -> 8 | F15: =B15*C15*E15 -> 24000
A16: Líder de atividades / experiências | B16: 1 | C16: 4000 | D16: 0 | E16: =IF(D16=1,12*Premissas!$B$21,Premissas!$B$22) -> 8 | F16: =B16*C16*E16 -> 32000
A17: Esportes aquáticos / guia | B17: 1 | C17: 2800 | D17: 0 | E17: =IF(D17=1,12*Premissas!$B$21,Premissas!$B$22) -> 8 | F17: =B17*C17*E17 -> 22400
... A27: Lavanderia | B27: 1 | C27: 1800 | D27: 0 | E27: =IF(D27=1,12*Premissas!$B$21,Premissas!$B$22) -> 8 | F27: =B27*C27*E27 -> 14400
A28: Folha bruta | B28: =SUM(B6:B27) -> 28 | F28: =SUM(F6:F27) -> 1250000
A29: Encargos operacionais (viagens, treinamento, uniformes, recrutamento) | F29: =F28*Premissas!$B$19 -> 275000
A30: Encargos sociais da bandeira | F30: =F28*Premissas!$B$20 -> 62500
A31: CUSTO ANUAL TOTAL DA TRIPULAÇÃO | F31: =SUM(F28:F30) -> 1587500
A33: Configuração B — 24 cabines / 48 pax
A34: Função | B34: Qtd | C34: €/mês | D34: Posto-chave (1=sim) | E34: Meses pagos | F34: Custo anual (€)
A35: Comandante (Master) | B35: 1 | C35: 10000 | D35: 1 | E35: =IF(D35=1,12*Premissas!$B$21,Premissas!$B$22) -> 15.6 | F35: =B35*C35*E35 -> 156000
A36: Imediato (Chief Officer) | B36: 1 | C36: 6000 | D36: 1 | E36: =IF(D36=1,12*Premissas!$B$21,Premissas!$B$22) -> 15.6 | F36: =B36*C36*E36 -> 93600
A37: Contramestre (Bosun) | B37: 1 | C37: 3200 | D37: 0 | E37: =IF(D37=1,12*Premissas!$B$21,Premissas!$B$22) -> 8 | F37: =B37*C37*E37 -> 25600
A38: Marinheiros / tender drivers | B38: 2 | C38: 2600 | D38: 0 | E38: =IF(D38=1,12*Premissas!$B$21,Premissas!$B$22) -> 8 | F38: =B38*C38*E38 -> 41600
A39: Chefe de Máquinas | B39: 1 | C39: 8000 | D39: 1 | E39: =IF(D39=1,12*Premissas!$B$21,Premissas!$B$22) -> 15.6 | F39: =B39*C39*E39 -> 124800
A40: 2º Maquinista | B40: 1 | C40: 5000 | D40: 1 | E40: =IF(D40=1,12*Premissas!$B$21,Premissas!$B$22) -> 15.6 | F40: =B40*C40*E40 -> 78000
A41: Hotel Manager | B41: 1 | C41: 5500 | D41: 1 | E41: =IF(D41=1,12*Premissas!$B$21,Premissas!$B$22) -> 15.6 | F41: =B41*C41*E41 -> 85800
A42: Recepção / Purser | B42: 1 | C42: 2800 | D42: 0 | E42: =IF(D42=1,12*Premissas!$B$21,Premissas!$B$22) -> 8 | F42: =B42*C42*E42 -> 22400
A43: Atividades / esportes aquáticos | B43: 1 | C43: 3000 | D43: 0 | E43: =IF(D43=1,12*Premissas!$B$21,Premissas!$B$22) -> 8 | F43: =B43*C43*E43 -> 24000
A44: Chef executivo | B44: 1 | C44: 6000 | D44: 1 | E44: =IF(D44=1,12*Premissas!$B$21,Premissas!$B$22) -> 15.6 | F44: =B44*C44*E44 -> 93600
A45: Sous chef | B45: 1 | C45: 4000 | D45: 0 | E45: =IF(D45=1,12*Premissas!$B$21,Premissas!$B$22) -> 8 | F45: =B45*C45*E45 -> 32000
A46: Cozinheiro | B46: 1 | C46: 2800 | D46: 0 | E46: =IF(D46=1,12*Premissas!$B$21,Premissas!$B$22) -> 8 | F46: =B46*C46*E46 -> 22400
... A51: Camareiros | B51: 2 | C51: 2100 | D51: 0 | E51: =IF(D51=1,12*Premissas!$B$21,Premissas!$B$22) -> 8 | F51: =B51*C51*E51 -> 33600
A52: Folha bruta | B52: =SUM(B35:B51) -> 20 | F52: =SUM(F35:F51) -> 935800
A53: Encargos operacionais (viagens, treinamento, uniformes, recrutamento) | F53: =F52*Premissas!$B$19 -> 205876
A54: Encargos sociais da bandeira | F54: =F52*Premissas!$B$20 -> 46790
A55: CUSTO ANUAL TOTAL DA TRIPULAÇÃO | F55: =SUM(F52:F54) -> 1188466
...

Sheet CAPEX_Construcao
A1: CAPEX de construção nova — 72 pax / ~60–65 m — três padrões
A2: Custo-base por região a partir de €/leito (pesquisa de estaleiros). Distribuição percentual = ESTIMATIVA (não há fonte pública de breakdown). Editar células azuis.
A4: 1. Custo de construção (estaleiro turco, base) por padrão
A5: Item | B5: Premium funcional | C5: Luxury boutique | D5: Ultra-luxury | F5: % PF | G5: % LB | H5: % UL
A6: Leitos | B6: =Premissas!$B$44 -> 72 | C6: =Premissas!$B$44 -> 72 | D6: =Premissas!$B$44 -> 72
A7: Custo-base por leito — referência Holanda (€) | B7: 560000 | C7: 775000 | D7: 1125000 | F7: Faixas: €520–600k / €700–850k / €1,0–1,25M por leito (ESTIMATIVA, mediana dos comparáveis ~€570k)
A8: Índice de custo da região escolhida (Turquia) | B8: 0.75 | C8: 0.75 | D8: 0.75 | F8: Turquia 0,65–0,80 vs. Holanda = 1,00 (ver tabela regional abaixo)
A9: Preço de contrato do estaleiro (antes de contingência) | B9: =B6*B7*B8 -> 30240000 | C9: =C6*C7*C8 -> 41850000 | D9: =D6*D7*D8 -> 60750000
A11: Breakdown do preço de contrato
A12: Projeto naval, engenharia e design de interiores | B12: =B$9*F12 -> 1512000 | C12: =C$9*G12 -> 2511000 | D12: =D$9*H12 -> 4252500 | F12: 0.05 | G12: 0.06 | H12: 0.07
A13: Casco e superestrutura | B13: =B$9*F13 -> 6652800 | C13: =C$9*G13 -> 7951500 | D13: =D$9*H13 -> 9720000 | F13: 0.22 | G13: 0.19 | H13: 0.16
A14: Propulsão e máquinas (motores, eixos, estabilizadores, thrusters) | B14: =B$9*F14 -> 3931200 | C14: =C$9*G14 -> 5022000 | D14: =D$9*H14 -> 6682500 | F14: 0.13 | G14: 0.12 | H14: 0.11
A15: Geradores e sistema elétrico (híbrido opcional) | B15: =B$9*F15 -> 2721600 | C15: =C$9*G15 -> 3766500 | D15: =D$9*H15 -> 5467500 | F15: 0.09 | G15: 0.09 | H15: 0.09
A16: HVAC, tubulações, água, esgoto e sistemas | B16: =B$9*F16 -> 3024000 | C16: =C$9*G16 -> 4185000 | D16: =D$9*H16 -> 5467500 | F16: 0.1 | G16: 0.1 | H16: 0.09
A17: Interiores e hotelaria (cabines, áreas sociais, marcenaria, teca) | B17: =B$9*F17 -> 6652800 | C17: =C$9*G17 -> 10462500 | D17: =D$9*H17 -> 17617500 | F17: 0.22 | G17: 0.25 | H17: 0.29
A18: Cozinha, lavanderia e equipamentos de hotel | B18: =B$9*F18 -> 907200 | C18: =C$9*G18 -> 1255500 | D18: =D$9*H18 -> 1822500 | F18: 0.03 | G18: 0.03 | H18: 0.03
A19: Navegação, comunicações, TI/AV, Starlink | B19: =B$9*F19 -> 907200 | C19: =C$9*G19 -> 1255500 | D19: =D$9*H19 -> 1822500 | F19: 0.03 | G19: 0.03 | H19: 0.03
A20: Segurança: salvatagem (LSA), combate a incêndio, MES | B20: =B$9*F20 -> 1209600 | C20: =C$9*G20 -> 1464750 | D20: =D$9*H20 -> 1822500 | F20: 0.04 | G20: 0.035 | H20: 0.03
A21: Classe, bandeira, certificações, provas de mar | B21: =B$9*F21 -> 604800 | C21: =C$9*G21 -> 837000 | D21: =D$9*H21 -> 911250 | F21: 0.02 | G21: 0.02 | H21: 0.015
A22: Tenders, Zodiacs, plataforma de marina, water toys | B22: =B$9*F22 -> 604800 | C22: =C$9*G22 -> 1046250 | D22: =D$9*H22 -> 1822500 | F22: 0.02 | G22: 0.025 | H22: 0.03
A23: Enxoval e operacional (OS&E: roupa de cama, louça, uniformes, peças) | B23: =B$9*F23 -> 604800 | C23: =C$9*G23 -> 837000 | D23: =D$9*H23 -> 1518750 | F23: 0.02 | G23: 0.02 | H23: 0.025
A24: Equipe de supervisão do armador e custos de obra | B24: =B$9*F24 -> 907200 | C24: =C$9*G24 -> 1255500 | D24: =D$9*H24 -> 1822500 | F24: 0.03 | G24: 0.03 | H24: 0.03
A25: Soma (verificação = 100%) | B25: =SUM(B12:B24) -> 30240000 | C25: =SUM(C12:C24) -> 41850000 | D25: =SUM(D12:D24) -> 60750000 | F25: =SUM(F12:F24) -> 1 | G25: =SUM(G12:G24) -> 1 | H25: =SUM(H12:H24) -> 1
A27: Contingência (% do contrato) | B27: =B9*F27 -> 2116800 | C27: =C9*G27 -> 3348000 | D27: =D9*H27 -> 6075000 | F27: 0.07 | G27: 0.08 | H27: 0.1
A28: Juros pré-entrega, legal, refund guarantee, seguros de construção (%) | B28: =B9*F28 -> 907200 | C28: =C9*G28 -> 1255500 | D28: =D9*H28 -> 1822500 | F28: 0.03 | G28: 0.03 | H28: 0.03
A29: Pré-operacional (recrutamento, treinamento, viagem inaugural, lançamento, capital de giro) (%) | B29: =B9*F29 -> 907200 | C29: =C9*G29 -> 1255500 | D29: =D9*H29 -> 1822500 | F29: 0.03 | G29: 0.03 | H29: 0.03
A30: CUSTO TOTAL ATÉ A ENTRADA EM OPERAÇÃO | B30: =B9+B27+B28+B29 -> 34171200 | C30: =C9+C27+C28+C29 -> 47709000 | D30: =D9+D27+D28+D29 -> 70470000
A31: Custo total por leito | B31: =B30/B6 -> 474600 | C31: =C30/C6 -> 662625 | D31: =D30/D6 -> 978750
A32: Prazo contrato → entrega (meses) | B32: 22–26 | C32: 24–30 | D32: 28–36
A33: Prazo decisão → 1ª temporada (meses) | B33: 30–36 | C33: 32–40 | D33: 36–44
A35: 2. Custo total por região (Luxury boutique, 72 pax)
A36: Região | B36: Índice baixo | C36: Índice alto | D36: Custo total baixo | F36: Custo total alto | G36: Observação
A37: Holanda / Noruega / Alemanha | B37: 1 | C37: 1 | D37: =$C$30/$C$8*B37 -> 63612000 | F37: =$C$30/$C$8*C37 -> 63612000 | G37: Referência (De Hoop: Silver Origin €680k/leito)
A38: Itália | B38: 0.95 | C38: 1.05 | D38: =$C$30/$C$8*B38 -> 60431400 | F38: =$C$30/$C$8*C38 -> 66792600 | G38: Mercado premium de superiates
A39: Espanha / Portugal | B39: 0.8 | C39: 0.9 | D39: =$C$30/$C$8*B39 -> 50889600 | F39: =$C$30/$C$8*C39 -> 57250800 | G39: West Sea: €357–400k/leito em navios de 176–196 pax
A40: Croácia / Grécia | B40: 0.75 | C40: 0.9 | D40: =$C$30/$C$8*B40 -> 47709000 | F40: =$C$30/$C$8*C40 -> 57250800 | G40: Brodosplit (risco financeiro); Voyager feito em Perama
A41: Turquia | B41: 0.65 | C41: 0.8 | D41: =$C$30/$C$8*B41 -> 41347800 | F41: =$C$30/$C$8*C41 -> 50889600 | G41: Mão de obra ~40% da europeia; equipamentos a preço global
A42: Vietnã / China | B42: 0.6 | C42: 0.75 | D42: =$C$30/$C$8*B42 -> 38167200 | F42: =$C$30/$C$8*C42 -> 47709000 | G42: +€0,5–1M de viagem de entrega até o Med

Sheet Charter
A1: Modelo 3 — Charter de terceiros: custo efetivo para a QIMO
A2: Tarifas CONFIRMADAS por faixas (brokers/Variety). APA, IVA e gorjetas = práticas de mercado confirmadas. Excursões = ESTIMATIVA.
A4: Navio 72 pax / 36 cab (ex.: Variety Voyager)
A5: Componente | B5: Conservador | C5: Base | D5: Premium
A6: Cabines / passageiros | B6: 36 | C6: 72
A7: Tarifa de full charter (€/semana) | B7: 247650 | C7: 280000 | D7: 342000 | F7: Broker: €247.650 (baixa) – €342.000 (alta) + despesas; Variety direto via Goolets: US$213k (jul/2025)
A8: APA — provisões, bebidas, combustível extra, taxas portuárias (% da tarifa) | B8: 0.3 | C8: 0.32 | D8: 0.35 | F8: 30–40% da tarifa (CONFIRMADO, prática de broker)
A9: IVA sobre charter (Grécia efetivo) | B9: 0.12 | C9: 0.12 | D9: 0.12 | F9: Grécia ~12% efetivo; Croácia 13%; Itália 22%
A10: Gorjetas da tripulação (% da tarifa) | B10: 0.08 | C10: 0.1 | D10: 0.12 | F10: Diretriz MYBA/brokers: 5–15%, padrão 10%
A11: Excursões/experiências em terra (€/pax/semana) | B11: 300 | C11: 450 | D11: 700 | F11: ESTIMATIVA: 5 dias × €60–140/pax
A12: Posicionamento / mínimos de consumo (€/semana) | B12: 0 | C12: 0 | D12: 15000 | F12: Normalmente zero dentro da área de operação do navio; cobrado fora dela
A13: CUSTO DO NAVIO (tarifa + APA + IVA) | B13: =B7*(1+B8+B9)+B12 -> 351663 | C13: =C7*(1+C8+C9)+C12 -> 403200 | D13: =D7*(1+D8+D9)+D12 -> 517740
A14: CUSTO TOTAL DA SEMANA (+ gorjetas + excursões) | B14: =B13+B7*B10+B11*$C$6 -> 393075 | C14: =C13+C7*C10+C11*$C$6 -> 463600 | D14: =D13+D7*D10+D11*$C$6 -> 609180
A15: …por cabine | B15: =B14/$B$6 -> 10918.75 | C15: =C14/$B$6 -> 12877.778 | D15: =D14/$B$6 -> 16921.667
A16: …por passageiro | B16: =B14/$C$6 -> 5459.375 | C16: =C14/$C$6 -> 6438.8889 | D16: =D14/$C$6 -> 8460.8333
A18: Navio ~48–49 pax / 24 cab (ex.: Galileo, Harmony V)
A19: Componente | B19: Conservador | C19: Base | D19: Premium
A20: Cabines / passageiros | B20: 24 | C20: 49
A21: Tarifa de full charter (€/semana) | B21: 92000 | C21: 135000 | D21: 172900 | F21: Galileo €92k (mar–abr) / €121,9k / €166,7k (mai–jun, set); Harmony V €129,4–172,9k
A22: APA — provisões, bebidas, combustível extra, taxas portuárias (% da tarifa) | B22: 0.3 | C22: 0.32 | D22: 0.35 | F22: 30–40% da tarifa (CONFIRMADO, prática de broker)
A23: IVA sobre charter (Grécia efetivo) | B23: 0.12 | C23: 0.12 | D23: 0.12 | F23: Grécia ~12% efetivo; Croácia 13%; Itália 22%
A24: Gorjetas da tripulação (% da tarifa) | B24: 0.08 | C24: 0.1 | D24: 0.12 | F24: Diretriz MYBA/brokers: 5–15%, padrão 10%
A25: Excursões/experiências em terra (€/pax/semana) | B25: 300 | C25: 450 | D25: 700 | F25: ESTIMATIVA: 5 dias × €60–140/pax
A26: Posicionamento / mínimos de consumo (€/semana) | B26: 0 | C26: 0 | D26: 15000 | F26: Normalmente zero dentro da área de operação do navio; cobrado fora dela
A27: CUSTO DO NAVIO (tarifa + APA + IVA) | B27: =B21*(1+B22+B23)+B26 -> 130640 | C27: =C21*(1+C22+C23)+C26 -> 194400 | D27: =D21*(1+D22+D23)+D26 -> 269163
A28: CUSTO TOTAL DA SEMANA (+ gorjetas + excursões) | B28: =B27+B21*B24+B25*$C$20 -> 152700 | C28: =C27+C21*C24+C25*$C$20 -> 229950 | D28: =D27+D21*D24+D25*$C$20 -> 324211
A29: …por cabine | B29: =B28/$B$20 -> 6362.5 | C29: =C28/$B$20 -> 9581.25 | D29: =D28/$B$20 -> 13508.792
A30: …por passageiro | B30: =B28/$C$20 -> 3116.3265 | C30: =C28/$C$20 -> 4692.8571 | D30: =D28/$C$20 -> 6616.551
A32: Navio ~36–40 pax / 18–20 cab (Croácia / Callisto)
A33: Componente | B33: Conservador | C33: Base | D33: Premium
A34: Cabines / passageiros | B34: 18 | C34: 36
A35: Tarifa de full charter (€/semana) | B35: 76000 | C35: 95000 | D35: 115000 | F35: Karizma €84–95k; Lastavica €76–87k; Callisto a partir de €115k
A36: APA — provisões, bebidas, combustível extra, taxas portuárias (% da tarifa) | B36: 0.3 | C36: 0.32 | D36: 0.35 | F36: 30–40% da tarifa (CONFIRMADO, prática de broker)
A37: IVA sobre charter (Grécia efetivo) | B37: 0.12 | C37: 0.12 | D37: 0.12 | F37: Grécia ~12% efetivo; Croácia 13%; Itália 22%
A38: Gorjetas da tripulação (% da tarifa) | B38: 0.08 | C38: 0.1 | D38: 0.12 | F38: Diretriz MYBA/brokers: 5–15%, padrão 10%
A39: Excursões/experiências em terra (€/pax/semana) | B39: 300 | C39: 450 | D39: 700 | F39: ESTIMATIVA: 5 dias × €60–140/pax
A40: Posicionamento / mínimos de consumo (€/semana) | B40: 0 | C40: 0 | D40: 15000 | F40: Normalmente zero dentro da área de operação do navio; cobrado fora dela
A41: CUSTO DO NAVIO (tarifa + APA + IVA) | B41: =B35*(1+B36+B37)+B40 -> 107920 | C41: =C35*(1+C36+C37)+C40 -> 136800 | D41: =D35*(1+D36+D37)+D40 -> 184050
A42: CUSTO TOTAL DA SEMANA (+ gorjetas + excursões) | B42: =B41+B35*B38+B39*$C$34 -> 124800 | C42: =C41+C35*C38+C39*$C$34 -> 162500 | D42: =D41+D35*D38+D39*$C$34 -> 223050
A43: …por cabine | B43: =B42/$B$34 -> 6933.3333 | C43: =C42/$B$34 -> 9027.7778 | D43: =D42/$B$34 -> 12391.667
...

Sheet Projecao
A1: Projeção de 10 anos — 6 opções × 3 cenários (desalavancado)
A2: Colunas: anos -2 e -1 = construção; 0 = entrega/compra; 1–10 = operação. Valores nominais. Todas as linhas são fórmulas ligadas às Premissas.
B4: C · 36 cab/72 pax · NOVO — cenário Conservador
B5: Ano | C5: -2 | D5: -1 | E5: 0 | F5: 1 | G5: 2 | H5: 3 | I5: 4 | J5: 5 | K5: 6 | L5: 7 | M5: 8 | N5: 9 | O5: 10
B6: Semanas operadas | C6: =IF(C$5>=1,Premissas!$B$29*IF(C$5=1,Premissas!$B$37,1),0) -> 0 | D6: =IF(D$5>=1,Premissas!$B$29*IF(D$5=1,Premissas!$B$37,1),0) -> 0 | E6: =IF(E$5>=1,Premissas!$B$29*IF(E$5=1,Premissas!$B$37,1),0) -> 0 | F6: =IF(F$5>=1,Premissas!$B$29*IF(F$5=1,Premissas!$B$37,1),0) -> 15 | G6: =IF(G$5>=1,Premissas!$B$29*IF(G$5=1,Premissas!$B$37,1),0) -> 20 | H6: =IF(H$5>=1,Premissas!$B$29*IF(H$5=1,Premissas!$B$37,1),0) -> 20 | I6: =IF(I$5>=1,Premissas!$B$29*IF(I$5=1,Premissas!$B$37,1),0) -> 20 | J6: =IF(J$5>=1,Premissas!$B$29*IF(J$5=1,Premissas!$B$37,1),0) -> 20 | ... O6: =IF(O$5>=1,Premissas!$B$29*IF(O$5=1,Premissas!$B$37,1),0) -> 20
B7: Semanas QIMO | C7: =MIN(C6,Premissas!$B$30) -> 0 | D7: =MIN(D6,Premissas!$B$30) -> 0 | E7: =MIN(E6,Premissas!$B$30) -> 0 | F7: =MIN(F6,Premissas!$B$30) -> 6 | G7: =MIN(G6,Premissas!$B$30) -> 6 | H7: =MIN(H6,Premissas!$B$30) -> 6 | I7: =MIN(I6,Premissas!$B$30) -> 6 | J7: =MIN(J6,Premissas!$B$30) -> 6 | ... O7: =MIN(O6,Premissas!$B$30) -> 6
B8: Semanas venda de cabines | C8: =MIN(C6-C7,Premissas!$B$31) -> 0 | D8: =MIN(D6-D7,Premissas!$B$31) -> 0 | E8: =MIN(E6-E7,Premissas!$B$31) -> 0 | F8: =MIN(F6-F7,Premissas!$B$31) -> 4 | G8: =MIN(G6-G7,Premissas!$B$31) -> 4 | H8: =MIN(H6-H7,Premissas!$B$31) -> 4 | I8: =MIN(I6-I7,Premissas!$B$31) -> 4 | J8: =MIN(J6-J7,Premissas!$B$31) -> 4 | ... O8: =MIN(O6-O7,Premissas!$B$31) -> 4
B9: Semanas charter terceiros | C9: =C6-C7-C8 -> 0 | D9: =D6-D7-D8 -> 0 | E9: =E6-E7-E8 -> 0 | F9: =F6-F7-F8 -> 5 | G9: =G6-G7-G8 -> 10 | H9: =H6-H7-H8 -> 10 | I9: =I6-I7-I8 -> 10 | J9: =J6-J7-J8 -> 10 | ... O9: =O6-O7-O8 -> 10
B10: Índice de tarifa | C10: =IF(C$5>=1,(1+Premissas!$B$8)^(C$5-1),0) -> 0 | D10: =IF(D$5>=1,(1+Premissas!$B$8)^(D$5-1),0) -> 0 | E10: =IF(E$5>=1,(1+Premissas!$B$8)^(E$5-1),0) -> 0 | F10: =IF(F$5>=1,(1+Premissas!$B$8)^(F$5-1),0) -> 1 | G10: =IF(G$5>=1,(1+Premissas!$B$8)^(G$5-1),0) -> 1.025 | H10: =IF(H$5>=1,(1+Premissas!$B$8)^(H$5-1),0) -> 1.050625 | I10: =IF(I$5>=1,(1+Premissas!$B$8)^(I$5-1),0) -> 1.0768906 | J10: =IF(J$5>=1,(1+Premissas!$B$8)^(J$5-1),0) -> 1.1038129 | ... O10: =IF(O$5>=1,(1+Premissas!$B$8)^(O$5-1),0) -> 1.248863
B11: Índice de custo | C11: =IF(C$5>=1,(1+Premissas!$B$9)^(C$5-1),0) -> 0 | D11: =IF(D$5>=1,(1+Premissas!$B$9)^(D$5-1),0) -> 0 | E11: =IF(E$5>=1,(1+Premissas!$B$9)^(E$5-1),0) -> 0 | F11: =IF(F$5>=1,(1+Premissas!$B$9)^(F$5-1),0) -> 1 | G11: =IF(G$5>=1,(1+Premissas!$B$9)^(G$5-1),0) -> 1.03 | H11: =IF(H$5>=1,(1+Premissas!$B$9)^(H$5-1),0) -> 1.0609 | I11: =IF(I$5>=1,(1+Premissas!$B$9)^(I$5-1),0) -> 1.092727 | J11: =IF(J$5>=1,(1+Premissas!$B$9)^(J$5-1),0) -> 1.1255088 | ... O11: =IF(O$5>=1,(1+Premissas!$B$9)^(O$5-1),0) -> 1.3047732
B12: Receita — QIMO (preço de transferência = mercado) | C12: =C7*Premissas!$B$77*Premissas!$B$32*C10 -> 0 | D12: =D7*Premissas!$B$77*Premissas!$B$32*D10 -> 0 | E12: =E7*Premissas!$B$77*Premissas!$B$32*E10 -> 0 | F12: =F7*Premissas!$B$77*Premissas!$B$32*F10 -> 1620000 | G12: =G7*Premissas!$B$77*Premissas!$B$32*G10 -> 1660500 | H12: =H7*Premissas!$B$77*Premissas!$B$32*H10 -> 1702012.5 | I12: =I7*Premissas!$B$77*Premissas!$B$32*I10 -> 1744562.8 | J12: =J7*Premissas!$B$77*Premissas!$B$32*J10 -> 1788176.9 | ... O12: =O7*Premissas!$B$77*Premissas!$B$32*O10 -> 2023158
B13: Receita — charter de terceiros (líq. comissão) | C13: =C9*Premissas!$B$77*Premissas!$B$32*(1-Premissas!$B$12)*C10 -> 0 | D13: =D9*Premissas!$B$77*Premissas!$B$32*(1-Premissas!$B$12)*D10 -> 0 | E13: =E9*Premissas!$B$77*Premissas!$B$32*(1-Premissas!$B$12)*E10 -> 0 | F13: =F9*Premissas!$B$77*Premissas!$B$32*(1-Premissas!$B$12)*F10 -> 1147500 | G13: =G9*Premissas!$B$77*Premissas!$B$32*(1-Premissas!$B$12)*G10 -> 2352375 | H13: =H9*Premissas!$B$77*Premissas!$B$32*(1-Premissas!$B$12)*H10 -> 2411184.4 | I13: =I9*Premissas!$B$77*Premissas!$B$32*(1-Premissas!$B$12)*I10 -> 2471464 | J13: =J9*Premissas!$B$77*Premissas!$B$32*(1-Premissas!$B$12)*J10 -> 2533250.6 | ... O13: =O9*Premissas!$B$77*Premissas!$B$32*(1-Premissas!$B$12)*O10 -> 2866140.5
B14: Receita — venda de cabines (líq. comissão) | C14: =C8*Premissas!$B$44*Premissas!$B$38*Premissas!$B$78*Premissas!$B$32*(1-Premissas!$B$12)*C10 -> 0 | D14: =D8*Premissas!$B$44*Premissas!$B$38*Premissas!$B$78*Premissas!$B$32*(1-Premissas!$B$12)*D10 -> 0 | E14: =E8*Premissas!$B$44*Premissas!$B$38*Premissas!$B$78*Premissas!$B$32*(1-Premissas!$B$12)*E10 -> 0 | F14: =F8*Premissas!$B$44*Premissas!$B$38*Premissas!$B$78*Premissas!$B$32*(1-Premissas!$B$12)*F10 -> 687398.4 | G14: =G8*Premissas!$B$44*Premissas!$B$38*Premissas!$B$78*Premissas!$B$32*(1-Premissas!$B$12)*G10 -> 704583.36 | H14: =H8*Premissas!$B$44*Premissas!$B$38*Premissas!$B$78*Premissas!$B$32*(1-Premissas!$B$12)*H10 -> 722197.94 | I14: =I8*Premissas!$B$44*Premissas!$B$38*Premissas!$B$78*Premissas!$B$32*(1-Premissas!$B$12)*I10 -> 740252.89 | J14: =J8*Premissas!$B$44*Premissas!$B$38*Premissas!$B$78*Premissas!$B$32*(1-Premissas!$B$12)*J10 -> 758759.21 | ... O14: =O8*Premissas!$B$44*Premissas!$B$38*Premissas!$B$78*Premissas!$B$32*(1-Premissas!$B$12)*O10 -> 858466.41
B15: Receita líquida a bordo | C15: =C6*Premissas!$B$44*Premissas!$B$14*Premissas!$B$13*C10 -> 0 | D15: =D6*Premissas!$B$44*Premissas!$B$14*Premissas!$B$13*D10 -> 0 | E15: =E6*Premissas!$B$44*Premissas!$B$14*Premissas!$B$13*E10 -> 0 | F15: =F6*Premissas!$B$44*Premissas!$B$14*Premissas!$B$13*F10 -> 145800 | G15: =G6*Premissas!$B$44*Premissas!$B$14*Premissas!$B$13*G10 -> 199260 | H15: =H6*Premissas!$B$44*Premissas!$B$14*Premissas!$B$13*H10 -> 204241.5 | I15: =I6*Premissas!$B$44*Premissas!$B$14*Premissas!$B$13*I10 -> 209347.54 | J15: =J6*Premissas!$B$44*Premissas!$B$14*Premissas!$B$13*J10 -> 214581.23 | ... O15: =O6*Premissas!$B$44*Premissas!$B$14*Premissas!$B$13*O10 -> 242778.96
B16: RECEITA TOTAL | C16: =SUM(C12:C15) -> 0 | D16: =SUM(D12:D15) -> 0 | E16: =SUM(E12:E15) -> 0 | F16: =SUM(F12:F15) -> 3600698.4 | G16: =SUM(G12:G15) -> 4916718.4 | H16: =SUM(H12:H15) -> 5039636.3 | I16: =SUM(I12:I15) -> 5165627.2 | J16: =SUM(J12:J15) -> 5294767.9 | ... O16: =SUM(O12:O15) -> 5990543.9
B17: Custos variáveis (combustível, alimentação, consumíveis) | C17: =-C6*(Premissas!$B$70*Premissas!$B$34/Premissas!$B$6+Premissas!$B$75)*Premissas!$B$33*C11 -> 0 | D17: =-D6*(Premissas!$B$70*Premissas!$B$34/Premissas!$B$6+Premissas!$B$75)*Premissas!$B$33*D11 -> 0 | E17: =-E6*(Premissas!$B$70*Premissas!$B$34/Premissas!$B$6+Premissas!$B$75)*Premissas!$B$33*E11 -> 0 | F17: =-F6*(Premissas!$B$70*Premissas!$B$34/Premissas!$B$6+Premissas!$B$75)*Premissas!$B$33*F11 -> -1055451.9 | G17: =-G6*(Premissas!$B$70*Premissas!$B$34/Premissas!$B$6+Premissas!$B$75)*Premissas!$B$33*G11 -> -1449487.3 | H17: =-H6*(Premissas!$B$70*Premissas!$B$34/Premissas!$B$6+Premissas!$B$75)*Premissas!$B$33*H11 -> -1492971.9 | I17: =-I6*(Premissas!$B$70*Premissas!$B$34/Premissas!$B$6+Premissas!$B$75)*Premissas!$B$33*I11 -> -1537761.1 | J17: =-J6*(Premissas!$B$70*Premissas!$B$34/Premissas!$B$6+Premissas!$B$75)*Premissas!$B$33*J11 -> -1583893.9 | ... O17: =-O6*(Premissas!$B$70*Premissas!$B$34/Premissas!$B$6+Premissas!$B$75)*Premissas!$B$33*O11 -> -1836167.1
B18: Custos fixos (tripulação, seguros, manutenção, gestão…) | C18: =-IF(C$5>=1,Premissas!$B$68*Premissas!$B$33*C11,0) -> 0 | D18: =-IF(D$5>=1,Premissas!$B$68*Premissas!$B$33*D11,0) -> 0 | E18: =-IF(E$5>=1,Premissas!$B$68*Premissas!$B$33*E11,0) -> 0 | F18: =-IF(F$5>=1,Premissas!$B$68*Premissas!$B$33*F11,0) -> -3733589.2 | G18: =-IF(G$5>=1,Premissas!$B$68*Premissas!$B$33*G11,0) -> -3845596.9 | H18: =-IF(H$5>=1,Premissas!$B$68*Premissas!$B$33*H11,0) -> -3960964.8 | I18: =-IF(I$5>=1,Premissas!$B$68*Premissas!$B$33*I11,0) -> -4079793.7 | J18: =-IF(J$5>=1,Premissas!$B$68*Premissas!$B$33*J11,0) -> -4202187.5 | ... O18: =-IF(O$5>=1,Premissas!$B$68*Premissas!$B$33*O11,0) -> -4871487.1
B19: EBITDA | C19: =C16+C17+C18 -> 0 | D19: =D16+D17+D18 -> 0 | E19: =E16+E17+E18 -> 0 | F19: =F16+F17+F18 -> -1188342.7 | G19: =G16+G17+G18 -> -378365.81 | H19: =H16+H17+H18 -> -414300.38 | I19: =I16+I17+I18 -> -451927.57 | J19: =J16+J17+J18 -> -491313.53 | ... O19: =O16+O17+O18 -> -717110.31
B20: Margem EBITDA | C20: =IF(C16=0,0,C19/C16) -> 0 | D20: =IF(D16=0,0,D19/D16) -> 0 | E20: =IF(E16=0,0,E19/E16) -> 0 | F20: =IF(F16=0,0,F19/F16) -> -0.33003117 | G20: =IF(G16=0,0,G19/G16) -> -0.076954949 | H20: =IF(H16=0,0,H19/H16) -> -0.082208388 | I20: =IF(I16=0,0,I19/I16) -> -0.087487453 | J20: =IF(J16=0,0,J19/J16) -> -0.09279227 | ... O20: =IF(O16=0,0,O19/O16) -> -0.11970705
B21: Depreciação (até o valor residual) | C21: =-IF(C$5>=1,Premissas!$B$52*(1-Premissas!$B$35)/10,0) -> 0 | D21: =-IF(D$5>=1,Premissas!$B$52*(1-Premissas!$B$35)/10,0) -> 0 | E21: =-IF(E$5>=1,Premissas!$B$52*(1-Premissas!$B$35)/10,0) -> 0 | F21: =-IF(F$5>=1,Premissas!$B$52*(1-Premissas!$B$35)/10,0) -> -2623995 | G21: =-IF(G$5>=1,Premissas!$B$52*(1-Premissas!$B$35)/10,0) -> -2623995 | H21: =-IF(H$5>=1,Premissas!$B$52*(1-Premissas!$B$35)/10,0) -> -2623995 | I21: =-IF(I$5>=1,Premissas!$B$52*(1-Premissas!$B$35)/10,0) -> -2623995 | J21: =-IF(J$5>=1,Premissas!$B$52*(1-Premissas!$B$35)/10,0) -> -2623995 | ... O21: =-IF(O$5>=1,Premissas!$B$52*(1-Premissas!$B$35)/10,0) -> -2623995
B22: EBIT | C22: =C19+C21 -> 0 | D22: =D19+D21 -> 0 | E22: =E19+E21 -> 0 | F22: =F19+F21 -> -3812337.7 | G22: =G19+G21 -> -3002360.8 | H22: =H19+H21 -> -3038295.4 | I22: =I19+I21 -> -3075922.6 | J22: =J19+J21 -> -3115308.5 | ... O22: =O19+O21 -> -3341105.3
B23: Impostos (CFC Brasil, sobre EBIT positivo) | C23: =-MAX(0,C22)*Premissas!$B$11 -> 0 | D23: =-MAX(0,D22)*Premissas!$B$11 -> 0 | E23: =-MAX(0,E22)*Premissas!$B$11 -> 0 | F23: =-MAX(0,F22)*Premissas!$B$11 -> 0 | G23: =-MAX(0,G22)*Premissas!$B$11 -> 0 | H23: =-MAX(0,H22)*Premissas!$B$11 -> 0 | I23: =-MAX(0,I22)*Premissas!$B$11 -> 0 | J23: =-MAX(0,J22)*Premissas!$B$11 -> 0 | ... O23: =-MAX(0,O22)*Premissas!$B$11 -> 0
B24: Docagens (dry dock) | C24: =-(IF(C$5=3,Premissas!$B$80,0)+IF(C$5=5,Premissas!$B$81,0)+IF(C$5=8,Premissas!$B$82,0)+IF(C$5=10,Premissas!$B$83,0))*C11 -> 0 | D24: =-(IF(D$5=3,Premissas!$B$80,0)+IF(D$5=5,Premissas!$B$81,0)+IF(D$5=8,Premissas!$B$82,0)+IF(D$5=10,Premissas!$B$83,0))*D11 -> 0 | E24: =-(IF(E$5=3,Premissas!$B$80,0)+IF(E$5=5,Premissas!$B$81,0)+IF(E$5=8,Premissas!$B$82,0)+IF(E$5=10,Premissas!$B$83,0))*E11 -> 0 | F24: =-(IF(F$5=3,Premissas!$B$80,0)+IF(F$5=5,Premissas!$B$81,0)+IF(F$5=8,Premissas!$B$82,0)+IF(F$5=10,Premissas!$B$83,0))*F11 -> 0 | G24: =-(IF(G$5=3,Premissas!$B$80,0)+IF(G$5=5,Premissas!$B$81,0)+IF(G$5=8,Premissas!$B$82,0)+IF(G$5=10,Premissas!$B$83,0))*G11 -> 0 | H24: =-(IF(H$5=3,Premissas!$B$80,0)+IF(H$5=5,Premissas!$B$81,0)+IF(H$5=8,Premissas!$B$82,0)+IF(H$5=10,Premissas!$B$83,0))*H11 -> -371315 | I24: =-(IF(I$5=3,Premissas!$B$80,0)+IF(I$5=5,Premissas!$B$81,0)+IF(I$5=8,Premissas!$B$82,0)+IF(I$5=10,Premissas!$B$83,0))*I11 -> 0 | J24: =-(IF(J$5=3,Premissas!$B$80,0)+IF(J$5=5,Premissas!$B$81,0)+IF(J$5=8,Premissas!$B$82,0)+IF(J$5=10,Premissas!$B$83,0))*J11 -> -900407.05 | ... O24: =-(IF(O$5=3,Premissas!$B$80,0)+IF(O$5=5,Premissas!$B$81,0)+IF(O$5=8,Premissas!$B$82,0)+IF(O$5=10,Premissas!$B$83,0))*O11 -> -1304773.2
B25: CAPEX de manutenção + refurb | C25: =-IF(C$5>=1,Premissas!$B$52*(Premissas!$B$84+IF(C$5=6,Premissas!$B$85,0))*C11,0) -> 0 | D25: =-IF(D$5>=1,Premissas!$B$52*(Premissas!$B$84+IF(D$5=6,Premissas!$B$85,0))*D11,0) -> 0 | E25: =-IF(E$5>=1,Premissas!$B$52*(Premissas!$B$84+IF(E$5=6,Premissas!$B$85,0))*E11,0) -> 0 | F25: =-IF(F$5>=1,Premissas!$B$52*(Premissas!$B$84+IF(F$5=6,Premissas!$B$85,0))*F11,0) -> -238545 | G25: =-IF(G$5>=1,Premissas!$B$52*(Premissas!$B$84+IF(G$5=6,Premissas!$B$85,0))*G11,0) -> -245701.35 | H25: =-IF(H$5>=1,Premissas!$B$52*(Premissas!$B$84+IF(H$5=6,Premissas!$B$85,0))*H11,0) -> -253072.39 | I25: =-IF(I$5>=1,Premissas!$B$52*(Premissas!$B$84+IF(I$5=6,Premissas!$B$85,0))*I11,0) -> -260664.56 | J25: =-IF(J$5>=1,Premissas!$B$52*(Premissas!$B$84+IF(J$5=6,Premissas!$B$85,0))*J11,0) -> -268484.5 | ... O25: =-IF(O$5>=1,Premissas!$B$52*(Premissas!$B$84+IF(O$5=6,Premissas!$B$85,0))*O11,0) -> -311247.12
B26: CAPEX inicial | C26: =-Premissas!$B$52*Premissas!$B$53 -> -9541800 | D26: =-Premissas!$B$52*Premissas!$B$54 -> -9541800 | E26: =-Premissas!$B$52*Premissas!$B$55 -> -28625400 | F26: 0 | G26: 0 | H26: 0 | I26: 0 | J26: 0 | K26: 0 | L26: 0 | M26: 0 | N26: 0 | O26: 0
B27: Valor residual (venda no ano 10) | C27: =IF(C$5=10,Premissas!$B$52*Premissas!$B$35,0) -> 0 | D27: =IF(D$5=10,Premissas!$B$52*Premissas!$B$35,0) -> 0 | E27: =IF(E$5=10,Premissas!$B$52*Premissas!$B$35,0) -> 0 | F27: =IF(F$5=10,Premissas!$B$52*Premissas!$B$35,0) -> 0 | G27: =IF(G$5=10,Premissas!$B$52*Premissas!$B$35,0) -> 0 | H27: =IF(H$5=10,Premissas!$B$52*Premissas!$B$35,0) -> 0 | I27: =IF(I$5=10,Premissas!$B$52*Premissas!$B$35,0) -> 0 | J27: =IF(J$5=10,Premissas!$B$52*Premissas!$B$35,0) -> 0 | ... O27: =IF(O$5=10,Premissas!$B$52*Premissas!$B$35,0) -> 21469050
B28: FLUXO DE CAIXA LIVRE (desalavancado) | C28: =C19+C23+C24+C25+C26+C27 -> -9541800 | D28: =D19+D23+D24+D25+D26+D27 -> -9541800 | E28: =E19+E23+E24+E25+E26+E27 -> -28625400 | F28: =F19+F23+F24+F25+F26+F27 -> -1426887.7 | G28: =G19+G23+G24+G25+G26+G27 -> -624067.16 | H28: =H19+H23+H24+H25+H26+H27 -> -1038687.8 | I28: =I19+I23+I24+I25+I26+I27 -> -712592.13 | J28: =J19+J23+J24+J25+J26+J27 -> -1660205.1 | ... O28: =O19+O23+O24+O25+O26+O27 -> 19135919
B29: FCL acumulado sem valor residual | C29: =C28-C27 -> -9541800 | D29: =C29+D28-D27 -> -19083600 | E29: =D29+E28-E27 -> -47709000 | F29: =E29+F28-F27 -> -49135888 | G29: =F29+G28-G27 -> -49759955 | H29: =G29+H28-H27 -> -50798643 | I29: =H29+I28-I27 -> -51511235 | J29: =I29+J28-J27 -> -53171440 | K29: =J29+K28-K27 -> -56192818 | ... O29: =N29+O28-O27 -> -61762508
B30: aux. payback | C30: 0 | D30: 0 | E30: 0 | F30: =IF(AND(E29<0,F29>=0),F$5-1+(-E29)/(F28-F27),0) -> 0 | G30: =IF(AND(F29<0,G29>=0),G$5-1+(-F29)/(G28-G27),0) -> 0 | H30: =IF(AND(G29<0,H29>=0),H$5-1+(-G29)/(H28-H27),0) -> 0 | I30: =IF(AND(H29<0,I29>=0),I$5-1+(-H29)/(I28-I27),0) -> 0 | J30: =IF(AND(I29<0,J29>=0),J$5-1+(-I29)/(J28-J27),0) -> 0 | K30: =IF(AND(J29<0,K29>=0),K$5-1+(-J29)/(K28-K27),0) -> 0 | L30: =IF(AND(K29<0,L29>=0),L$5-1+(-K29)/(L28-L27),0) -> 0 | M30: =IF(AND(L29<0,M29>=0),M$5-1+(-L29)/(M28-M27),0) -> 0 | ... O30: =IF(AND(N29<0,O29>=0),O$5-1+(-N29)/(O28-O27),0) -> 0
B31: TIR do projeto (10 anos, desalavancada) | C31: =IFERROR(IRR(C28:O28,0.05),IFERROR(IRR(C28:O28,-0.05),IF(SUM(C28:O28)<0,"negativa","n/d"))) -> -0.11933694
B32: VPL @ hurdle (data de entrega, ano 0) | C32: =C28*(1+Premissas!$B$10)^2+D28*(1+Premissas!$B$10)+E28+NPV(Premissas!$B$10,F28:O28) -> -50614480
B33: Payback (anos após entrega, sem residual) | C33: =IF(SUM(F30:O30)=0,"> 10",SUM(F30:O30)) -> > 10
B34: ROI em 10 anos (ganho líquido / investimento) | C34: =SUM(C28:O28)/-SUM(C26:E26) -> -0.84456722
B35: ROIC médio (NOPAT médio / capital investido) | C35: =AVERAGE(F22:O22)*(1-Premissas!$B$11)/-SUM(C26:E26) -> -0.044653027
B36: EBITDA ano 3 (regime) | C36: =H19 -> -414300.38
B37: Receita ano 3 | C37: =H16 -> 5039636.3
B38: Margem EBITDA ano 3 | C38: =H20 -> -0.082208388
B39: OPEX total ano 3 | C39: =-(H17+H18) -> 5453936.7
B40: Break-even EBITDA (semanas/ano, ano 3) | C40: =IFERROR(-H18/((H16+H17)/H6),"n/d") -> 22.336282
B41: CAPEX total | C41: =-SUM(C26:E26) -> 47709000
...

Sheet Sensib_Semanas
A1: Sensibilidade à utilização — 10 a 35 semanas/ano (cenário Base, ano de regime, € de 2026)
A2: TIR aproximada via RATE (fluxo constante + residual) — para análise rápida; a projeção completa está na aba Projecao.
A4: C · 36 cab/72 pax · NOVO
A5: Semanas/ano | B5: Semanas | C5: Receita | D5: OPEX | E5: EBITDA | F5: Margem | G5: FCL anual | H5: TIR ~10a | I5: Custo próprio/sem. | J5: Tarifa charter/sem.
A6: 10 semanas | B6: 10 | C6: =MIN(B6,Premissas!$C$30)*Premissas!$B$77*Premissas!$C$32+(B6-MIN(B6,Premissas!$C$30)-MIN(B6-MIN(B6,Premissas!$C$30),Premissas!$C$31))*Premissas!$B$77*Premissas!$C$32*(1-Premissas!$B$12)+MIN(B6-MIN(B6,Premissas!$C$30),Premissas!$C$31)*Premissas!$B$44*Premissas!$C$38*Premissas!$B$78*Premissas!$C$32*(1-Premissas!$B$12)+B6*Premissas!$B$44*Premissas!$B$14*Premissas!$B$13 -> 2937840 | D6: =B6*(Premissas!$B$70*Premissas!$C$34/Premissas!$B$6+Premissas!$B$75)*Premissas!$C$33+Premissas!$B$68*Premissas!$C$33 -> 3946883.3 | E6: =C6-D6 -> -1009043.3 | F6: =IF(C6=0,0,E6/C6) -> -0.34346435 | G6: =E6-MAX(0,E6-Premissas!$B$52*(1-Premissas!$C$35)/10)*Premissas!$B$11-(Premissas!$B$52*(Premissas!$B$84+Premissas!$B$85/10)+(Premissas!$B$80+Premissas!$B$81+Premissas!$B$82+Premissas!$B$83)/10) -> -1693424.3 | H6: =IFERROR(RATE(10,G6,-Premissas!$B$52,Premissas!$B$52*Premissas!$C$35),"< -10%") -> -0.1063898 | I6: =(D6+((Premissas!$B$52-Premissas!$B$52*Premissas!$C$35/(1+Premissas!$B$10)^10)*(Premissas!$B$10/(1-(1+Premissas!$B$10)^-10))+(Premissas!$B$52*(Premissas!$B$84+Premissas!$B$85/10)+(Premissas!$B$80+Premissas!$B$81+Premissas!$B$82+Premissas!$B$83)/10)))/B6 -> 1074924.8 | J6: =Premissas!$B$77*Premissas!$C$32 -> 300000
A7: 15 semanas | B7: 15 | C7: =MIN(B7,Premissas!$C$30)*Premissas!$B$77*Premissas!$C$32+(B7-MIN(B7,Premissas!$C$30)-MIN(B7-MIN(B7,Premissas!$C$30),Premissas!$C$31))*Premissas!$B$77*Premissas!$C$32*(1-Premissas!$B$12)+MIN(B7-MIN(B7,Premissas!$C$30),Premissas!$C$31)*Premissas!$B$44*Premissas!$C$38*Premissas!$B$78*Premissas!$C$32*(1-Premissas!$B$12)+B7*Premissas!$B$44*Premissas!$B$14*Premissas!$B$13 -> 4192080 | D7: =B7*(Premissas!$B$70*Premissas!$C$34/Premissas!$B$6+Premissas!$B$75)*Premissas!$C$33+Premissas!$B$68*Premissas!$C$33 -> 4223239 | E7: =C7-D7 -> -31158.957 | F7: =IF(C7=0,0,E7/C7) -> -0.0074328153 | G7: =E7-MAX(0,E7-Premissas!$B$52*(1-Premissas!$C$35)/10)*Premissas!$B$11-(Premissas!$B$52*(Premissas!$B$84+Premissas!$B$85/10)+(Premissas!$B$80+Premissas!$B$81+Premissas!$B$82+Premissas!$B$83)/10) -> -715539.96 | H7: =IFERROR(RATE(10,G7,-Premissas!$B$52,Premissas!$B$52*Premissas!$C$35),"< -10%") -> -0.07816134 | I7: =(D7+((Premissas!$B$52-Premissas!$B$52*Premissas!$C$35/(1+Premissas!$B$10)^10)*(Premissas!$B$10/(1-(1+Premissas!$B$10)^-10))+(Premissas!$B$52*(Premissas!$B$84+Premissas!$B$85/10)+(Premissas!$B$80+Premissas!$B$81+Premissas!$B$82+Premissas!$B$83)/10)))/B7 -> 735040.27 | J7: =Premissas!$B$77*Premissas!$C$32 -> 300000
A8: 20 semanas | B8: 20 | C8: =MIN(B8,Premissas!$C$30)*Premissas!$B$77*Premissas!$C$32+(B8-MIN(B8,Premissas!$C$30)-MIN(B8-MIN(B8,Premissas!$C$30),Premissas!$C$31))*Premissas!$B$77*Premissas!$C$32*(1-Premissas!$B$12)+MIN(B8-MIN(B8,Premissas!$C$30),Premissas!$C$31)*Premissas!$B$44*Premissas!$C$38*Premissas!$B$78*Premissas!$C$32*(1-Premissas!$B$12)+B8*Premissas!$B$44*Premissas!$B$14*Premissas!$B$13 -> 5515680 | D8: =B8*(Premissas!$B$70*Premissas!$C$34/Premissas!$B$6+Premissas!$B$75)*Premissas!$C$33+Premissas!$B$68*Premissas!$C$33 -> 4499594.6 | E8: =C8-D8 -> 1016085.4 | F8: =IF(C8=0,0,E8/C8) -> 0.18421761 | G8: =E8-MAX(0,E8-Premissas!$B$52*(1-Premissas!$C$35)/10)*Premissas!$B$11-(Premissas!$B$52*(Premissas!$B$84+Premissas!$B$85/10)+(Premissas!$B$80+Premissas!$B$81+Premissas!$B$82+Premissas!$B$83)/10) -> 331704.39 | H8: =IFERROR(RATE(10,G8,-Premissas!$B$52,Premissas!$B$52*Premissas!$C$35),"< -10%") -> -0.048842036 | I8: =(D8+((Premissas!$B$52-Premissas!$B$52*Premissas!$C$35/(1+Premissas!$B$10)^10)*(Premissas!$B$10/(1-(1+Premissas!$B$10)^-10))+(Premissas!$B$52*(Premissas!$B$84+Premissas!$B$85/10)+(Premissas!$B$80+Premissas!$B$81+Premissas!$B$82+Premissas!$B$83)/10)))/B8 -> 565097.98 | J8: =Premissas!$B$77*Premissas!$C$32 -> 300000
A9: 25 semanas | B9: 25 | C9: =MIN(B9,Premissas!$C$30)*Premissas!$B$77*Premissas!$C$32+(B9-MIN(B9,Premissas!$C$30)-MIN(B9-MIN(B9,Premissas!$C$30),Premissas!$C$31))*Premissas!$B$77*Premissas!$C$32*(1-Premissas!$B$12)+MIN(B9-MIN(B9,Premissas!$C$30),Premissas!$C$31)*Premissas!$B$44*Premissas!$C$38*Premissas!$B$78*Premissas!$C$32*(1-Premissas!$B$12)+B9*Premissas!$B$44*Premissas!$B$14*Premissas!$B$13 -> 6839280 | D9: =B9*(Premissas!$B$70*Premissas!$C$34/Premissas!$B$6+Premissas!$B$75)*Premissas!$C$33+Premissas!$B$68*Premissas!$C$33 -> 4775950.3 | E9: =C9-D9 -> 2063329.7 | F9: =IF(C9=0,0,E9/C9) -> 0.30168815 | G9: =E9-MAX(0,E9-Premissas!$B$52*(1-Premissas!$C$35)/10)*Premissas!$B$11-(Premissas!$B$52*(Premissas!$B$84+Premissas!$B$85/10)+(Premissas!$B$80+Premissas!$B$81+Premissas!$B$82+Premissas!$B$83)/10) -> 1378948.7 | H9: =IFERROR(RATE(10,G9,-Premissas!$B$52,Premissas!$B$52*Premissas!$C$35),"< -10%") -> -0.020379109 | I9: =(D9+((Premissas!$B$52-Premissas!$B$52*Premissas!$C$35/(1+Premissas!$B$10)^10)*(Premissas!$B$10/(1-(1+Premissas!$B$10)^-10))+(Premissas!$B$52*(Premissas!$B$84+Premissas!$B$85/10)+(Premissas!$B$80+Premissas!$B$81+Premissas!$B$82+Premissas!$B$83)/10)))/B9 -> 463132.61 | J9: =Premissas!$B$77*Premissas!$C$32 -> 300000
A10: 30 semanas | B10: 30 | C10: =MIN(B10,Premissas!$C$30)*Premissas!$B$77*Premissas!$C$32+(B10-MIN(B10,Premissas!$C$30)-MIN(B10-MIN(B10,Premissas!$C$30),Premissas!$C$31))*Premissas!$B$77*Premissas!$C$32*(1-Premissas!$B$12)+MIN(B10-MIN(B10,Premissas!$C$30),Premissas!$C$31)*Premissas!$B$44*Premissas!$C$38*Premissas!$B$78*Premissas!$C$32*(1-Premissas!$B$12)+B10*Premissas!$B$44*Premissas!$B$14*Premissas!$B$13 -> 8162880 | D10: =B10*(Premissas!$B$70*Premissas!$C$34/Premissas!$B$6+Premissas!$B$75)*Premissas!$C$33+Premissas!$B$68*Premissas!$C$33 -> 5052305.9 | E10: =C10-D10 -> 3110574.1 | F10: =IF(C10=0,0,E10/C10) -> 0.38106331 | G10: =E10-MAX(0,E10-Premissas!$B$52*(1-Premissas!$C$35)/10)*Premissas!$B$11-(Premissas!$B$52*(Premissas!$B$84+Premissas!$B$85/10)+(Premissas!$B$80+Premissas!$B$81+Premissas!$B$82+Premissas!$B$83)/10) -> 2098545.6 | H10: =IFERROR(RATE(10,G10,-Premissas!$B$52,Premissas!$B$52*Premissas!$C$35),"< -10%") -> -0.0012717662 | I10: =(D10+((Premissas!$B$52-Premissas!$B$52*Premissas!$C$35/(1+Premissas!$B$10)^10)*(Premissas!$B$10/(1-(1+Premissas!$B$10)^-10))+(Premissas!$B$52*(Premissas!$B$84+Premissas!$B$85/10)+(Premissas!$B$80+Premissas!$B$81+Premissas!$B$82+Premissas!$B$83)/10)))/B10 -> 395155.7 | J10: =Premissas!$B$77*Premissas!$C$32 -> 300000
A11: 35 semanas | B11: 35 | C11: =MIN(B11,Premissas!$C$30)*Premissas!$B$77*Premissas!$C$32+(B11-MIN(B11,Premissas!$C$30)-MIN(B11-MIN(B11,Premissas!$C$30),Premissas!$C$31))*Premissas!$B$77*Premissas!$C$32*(1-Premissas!$B$12)+MIN(B11-MIN(B11,Premissas!$C$30),Premissas!$C$31)*Premissas!$B$44*Premissas!$C$38*Premissas!$B$78*Premissas!$C$32*(1-Premissas!$B$12)+B11*Premissas!$B$44*Premissas!$B$14*Premissas!$B$13 -> 9486480 | D11: =B11*(Premissas!$B$70*Premissas!$C$34/Premissas!$B$6+Premissas!$B$75)*Premissas!$C$33+Premissas!$B$68*Premissas!$C$33 -> 5328661.6 | E11: =C11-D11 -> 4157818.4 | F11: =IF(C11=0,0,E11/C11) -> 0.43828885 | G11: =E11-MAX(0,E11-Premissas!$B$52*(1-Premissas!$C$35)/10)*Premissas!$B$11-(Premissas!$B$52*(Premissas!$B$84+Premissas!$B$85/10)+(Premissas!$B$80+Premissas!$B$81+Premissas!$B$82+Premissas!$B$83)/10) -> 2789726.9 | H11: =IFERROR(RATE(10,G11,-Premissas!$B$52,Premissas!$B$52*Premissas!$C$35),"< -10%") -> 0.016765355 | I11: =(D11+((Premissas!$B$52-Premissas!$B$52*Premissas!$C$35/(1+Premissas!$B$10)^10)*(Premissas!$B$10/(1-(1+Premissas!$B$10)^-10))+(Premissas!$B$52*(Premissas!$B$84+Premissas!$B$85/10)+(Premissas!$B$80+Premissas!$B$81+Premissas!$B$82+Premissas!$B$83)/10)))/B11 -> 346600.76 | J11: =Premissas!$B$77*Premissas!$C$32 -> 300000
A13: C · 36 cab/72 pax · USADO
A14: Semanas/ano | B14: Semanas | C14: Receita | D14: OPEX | E14: EBITDA | F14: Margem | G14: FCL anual | H14: TIR ~10a | I14: Custo próprio/sem. | J14: Tarifa charter/sem.
A15: 10 semanas | B15: 10 | C15: =MIN(B15,Premissas!$C$30)*Premissas!$C$77*Premissas!$C$32+(B15-MIN(B15,Premissas!$C$30)-MIN(B15-MIN(B15,Premissas!$C$30),Premissas!$C$31))*Premissas!$C$77*Premissas!$C$32*(1-Premissas!$B$12)+MIN(B15-MIN(B15,Premissas!$C$30),Premissas!$C$31)*Premissas!$C$44*Premissas!$C$38*Premissas!$C$78*Premissas!$C$32*(1-Premissas!$B$12)+B15*Premissas!$C$44*Premissas!$B$14*Premissas!$B$13 -> 2651940 | D15: =B15*(Premissas!$C$70*Premissas!$C$34/Premissas!$B$6+Premissas!$C$75)*Premissas!$C$33+Premissas!$C$68*Premissas!$C$33 -> 4006411.3 | E15: =C15-D15 -> -1354471.3 | F15: =IF(C15=0,0,E15/C15) -> -0.51074734 | G15: =E15-MAX(0,E15-Premissas!$C$52*(1-Premissas!$C$36)/10)*Premissas!$B$11-(Premissas!$C$52*(Premissas!$C$84+Premissas!$C$85/10)+(Premissas!$C$80+Premissas!$C$81+Premissas!$C$82+Premissas!$C$83)/10) -> -1959071.3 | H15: =IFERROR(RATE(10,G15,-Premissas!$C$52,Premissas!$C$52*Premissas!$C$36),"< -10%") -> -0.20589639 | I15: =(D15+((Premissas!$C$52-Premissas!$C$52*Premissas!$C$36/(1+Premissas!$B$10)^10)*(Premissas!$B$10/(1-(1+Premissas!$B$10)^-10))+(Premissas!$C$52*(Premissas!$C$84+Premissas!$C$85/10)+(Premissas!$C$80+Premissas!$C$81+Premissas!$C$82+Premissas!$C$83)/10)))/B15 -> 742238.7 | J15: =Premissas!$C$77*Premissas!$C$32 -> 270000
A16: 15 semanas | B16: 15 | C16: =MIN(B16,Premissas!$C$30)*Premissas!$C$77*Premissas!$C$32+(B16-MIN(B16,Premissas!$C$30)-MIN(B16-MIN(B16,Premissas!$C$30),Premissas!$C$31))*Premissas!$C$77*Premissas!$C$32*(1-Premissas!$B$12)+MIN(B16-MIN(B16,Premissas!$C$30),Premissas!$C$31)*Premissas!$C$44*Premissas!$C$38*Premissas!$C$78*Premissas!$C$32*(1-Premissas!$B$12)+B16*Premissas!$C$44*Premissas!$B$14*Premissas!$B$13 -> 3783780 | D16: =B16*(Premissas!$C$70*Premissas!$C$34/Premissas!$B$6+Premissas!$C$75)*Premissas!$C$33+Premissas!$C$68*Premissas!$C$33 -> 4282767 | E16: =C16-D16 -> -498986.96 | F16: =IF(C16=0,0,E16/C16) -> -0.13187526 | G16: =E16-MAX(0,E16-Premissas!$C$52*(1-Premissas!$C$36)/10)*Premissas!$B$11-(Premissas!$C$52*(Premissas!$C$84+Premissas!$C$85/10)+(Premissas!$C$80+Premissas!$C$81+Premissas!$C$82+Premissas!$C$83)/10) -> -1103587 | H16: =IFERROR(RATE(10,G16,-Premissas!$C$52,Premissas!$C$52*Premissas!$C$36),"< -10%") -> -0.14223699 | I16: =(D16+((Premissas!$C$52-Premissas!$C$52*Premissas!$C$36/(1+Premissas!$B$10)^10)*(Premissas!$B$10/(1-(1+Premissas!$B$10)^-10))+(Premissas!$C$52*(Premissas!$C$84+Premissas!$C$85/10)+(Premissas!$C$80+Premissas!$C$81+Premissas!$C$82+Premissas!$C$83)/10)))/B16 -> 513249.51 | J16: =Premissas!$C$77*Premissas!$C$32 -> 270000
